GTCEuStartupEvents.registry('gtceu:recipe_type', phoenixvine => {
    phoenixvine.create('phoenix_infuser')
        .category('phoenix')
        .setEUIO('in')
        .setMaxIOSize(2, 0, 2, 0)
        .setSlotOverlay(false, false, GuiTextures.SOLIDIFIER_OVERLAY)
        .setProgressBar(GuiTextures.PROGRESS_BAR_ARROW, FillDirection.LEFT_TO_RIGHT)
        .setSound(GTSoundEntries.JET_ENGINE);
        phoenixvine.create('phoenix_heart_hearth')
        .category('phoenix')
        .setEUIO('in')
        .setMaxIOSize(2, 1, 2, 1)
        .setSlotOverlay(false, false, GuiTextures.SOLIDIFIER_OVERLAY)
        .setProgressBar(GuiTextures.PROGRESS_BAR_ARROW, FillDirection.LEFT_TO_RIGHT)
        .setSound(GTSoundEntries.FURNACE);
});

/**GTCEuStartupEvents.registry('gtceu:machine', phoenixvine => {
    phoenixvine.create('phoenix_infuser', 'multiblock').machine((holder) => new $FusionReactorMachine(holder, GTValues.OpV))
        .rotationState(RotationState.NON_Y_AXIS)
        .recipeTypes('phoenix_infuser', 'phoenix_heart_hearth')
        .recipeModifiers([GTRecipeModifiers.PARALLEL_HATCH, GTRecipeModifiers.OC_PERFECT_SUBTICK])
        .appearanceBlock(() => Block.getBlock("kubejs:phoenix_enriched_tritanium_casing"))
        .pattern(definition => FactoryBlockPattern.start()
        .aisle("BBAAAAAAAAAAAAAAAAAAAAAAAAAAAAABB", "BBBAAAAAAAAAAAAAAAAAAAAAAAAAAABBB", "ABBBAAAAAAAAAAAAAAAAAAAAAAAAABBBA", "AABBBAAAAAAAAAAACAAAAAAAAAAABBBAA", "AAABBBAAAAAAAAACCCAAAAAAAAABBBAAA", "AAAABBBAAAAAAACCDCCAAAAAAABBBAAAA", "AAAAABBBAAAAACCEDECCAAAAABBBAAAAA", "AAAAAABBBAAACCFEDEFCCAAABBBAAAAAA", "AAAAAAABBBACCFGEHEGFCCABBBAAAAAAA", "AAAAAAAABBBCFIIEHEIIFCBBBAAAAAAAA", "AAAAAAAAABBBFIIEHEIIFBBBAAAAAAAAA", "AAAAAAAACCBBBFGEHEGFBBBCCAAAAAAAA", "AAAAAAACCFFBBBFEGEFBBBFFCCAAAAAAA", "AAAAAACCFIIFBBBEGEBBBFIIFCCAAAAAA", "AAAAACCFGIIGFBBBGBBBFGIIGFCCAAAAA", "AAAACCEEEEEEEEBBBBBEEEEEEEECCAAAA", "AAACCDDDHHHHGGGBBBGGGHHHHDDDCCAAA", "AAAACCEEEEEEEEBBBBBEEEEEEEECCAAAA", "AAAAACCFGIIGFBBBGBBBFGIIGFCCAAAAA", "AAAAAACCFIIFBBBEGEBBBFIIFCCAAAAAA", "AAAAAAACCFFBBBFEGEFBBBFFCCAAAAAAA", "AAAAAAAACCBBBFGEHEGFBBBCCAAAAAAAA", "AAAAAAAAABBBFIIEHEIIFBBBAAAAAAAAA", "AAAAAAAABBBCFIIEHEIIFCBBBAAAAAAAA", "AAAAAAABBBACCFGEHEGFCCABBBAAAAAAA", "AAAAAABBBAAACCFEDEFCCAAABBBAAAAAA", "AAAAABBBAAAAACCEDECCAAAAABBBAAAAA", "AAAABBBAAAAAAACCDCCAAAAAAABBBAAAA", "AAABBBAAAAAAAAACCCAAAAAAAAABBBAAA", "AABBBAAAAAAAAAAACAAAAAAAAAAABBBAA", "ABBBAAAAAAAAAAAAAAAAAAAAAAAAABBBA", "BBBAAAAAAAAAAAAAAAAAAAAAAAAAAABBB", "BBAAAAAAAAAAAAAAAAAAAAAAAAAAAAABB")
        .aisle("BBBAAAAAAAAAAAAAAAAAAAAAAAAAAABBB", "BAAAAAAAAAAAAAAAAAAAAAAAAAAAAAAAB", "BAAAAAAAAAAAAAAAAAAAAAAAAAAAAAAAB", "AAAAAAAAAAAAAAAAAAAAAAAAAAAAAAAAA", "AAAAAAAAAAAAAAAAAAAAAAAAAAAAAAAAA", "AAAAAAAAAAAAAAAAAAAAAAAAAAAAAAAAA", "AAAAAAAAAAAAAAAAAAAAAAAAAAAAAAAAA", "AAAAAAAAAAAAAAAAAAAAAAAAAAAAAAAAA", "AAAAAAAAAAAAAAAAAAAAAAAAAAAAAAAAA", "AAAAAAAAAAAAAAAAAAAAAAAAAAAAAAAAA", "AAAAAAAAAAAAAAAAAAAAAAAAAAAAAAAAA", "AAAAAAAAAAAAAAAAAAAAAAAAAAAAAAAAA", "AAAAAAAAAAAAAAAAAAAAAAAAAAAAAAAAA", "AAAAAAAAAAAAAAAAAAAAAAAAAAAAAAAAA", "AAAAAAAAAAAAAAAAAAAAAAAAAAAAAAAAA", "AAAAAAAAAAAAAGGGGGGGAAAAAAAAAAAAA", "AAAAAAAAAAAAJJGGGGGJJAAAAAAAAAAAA", "AAAAAAAAAAAAAGGGGGGGAAAAAAAAAAAAA", "AAAAAAAAAAAAAAAAAAAAAAAAAAAAAAAAA", "AAAAAAAAAAAAAAAAAAAAAAAAAAAAAAAAA", "AAAAAAAAAAAAAAAAAAAAAAAAAAAAAAAAA", "AAAAAAAAAAAAAAAAAAAAAAAAAAAAAAAAA", "AAAAAAAAAAAAAAAAAAAAAAAAAAAAAAAAA", "AAAAAAAAAAAAAAAAAAAAAAAAAAAAAAAAA", "AAAAAAAAAAAAAAAAAAAAAAAAAAAAAAAAA", "AAAAAAAAAAAAAAAAAAAAAAAAAAAAAAAAA", "AAAAAAAAAAAAAAAAAAAAAAAAAAAAAAAAA", "AAAAAAAAAAAAAAAAAAAAAAAAAAAAAAAAA", "AAAAAAAAAAAAAAAAAAAAAAAAAAAAAAAAA", "AAAAAAAAAAAAAAAAAAAAAAAAAAAAAAAAA", "BAAAAAAAAAAAAAAAAAAAAAAAAAAAAAAAB", "BAAAAAAAAAAAAAAAAAAAAAAAAAAAAAAAB", "BBBAAAAAAAAAAAAAAAAAAAAAAAAAAABBB")
        .aisle("ABBBAAAAAAAAAAAAAAAAAAAAAAAAABBBA", "BAAAAAAAAAAAAAAAAAAAAAAAAAAAAAAAB", "BAAAAAAAAAAAAAAAAAAAAAAAAAAAAAAAB", "BAAAAAAAAAAAAAAAAAAAAAAAAAAAAAAAB", "AAAAAAAAAAAAAAAAAAAAAAAAAAAAAAAAA", "AAAAAAAAAAAAAAAAAAAAAAAAAAAAAAAAA", "AAAAAAAAAAAAAAAAAAAAAAAAAAAAAAAAA", "AAAAAAAAAAAAAAAAAAAAAAAAAAAAAAAAA", "AAAAAAAAAAAAAAAAAAAAAAAAAAAAAAAAA", "AAAAAAAAAAAAAAAAAAAAAAAAAAAAAAAAA", "AAAAAAAAAAAAAAAAAAAAAAAAAAAAAAAAA", "AAAAAAAAAAAAAAAAAAAAAAAAAAAAAAAAA", "AAAAAAAAAAAAAAAAAAAAAAAAAAAAAAAAA", "AAAAAAAAAAAAAAAAAAAAAAAAAAAAAAAAA", "AAAAAAAAAAAAAAAAAAAAAAAAAAAAAAAAA", "AAAAAAAAAAAAAAAAAAAAAAAAAAAAAAAAA", "AAAAAAAAAAAJJAAAAAAAJJAAAAAAAAAAA", "AAAAAAAAAAAAAAAAAAAAAAAAAAAAAAAAA", "AAAAAAAAAAAAAAAAAAAAAAAAAAAAAAAAA", "AAAAAAAAAAAAAAAAAAAAAAAAAAAAAAAAA", "AAAAAAAAAAAAAAAAAAAAAAAAAAAAAAAAA", "AAAAAAAAAAAAAAAAAAAAAAAAAAAAAAAAA", "AAAAAAAAAAAAAAAAAAAAAAAAAAAAAAAAA", "AAAAAAAAAAAAAAAAAAAAAAAAAAAAAAAAA", "AAAAAAAAAAAAAAAAAAAAAAAAAAAAAAAAA", "AAAAAAAAAAAAAAAAAAAAAAAAAAAAAAAAA", "AAAAAAAAAAAAAAAAAAAAAAAAAAAAAAAAA", "AAAAAAAAAAAAAAAAAAAAAAAAAAAAAAAAA", "AAAAAAAAAAAAAAAAAAAAAAAAAAAAAAAAA", "BAAAAAAAAAAAAAAAAAAAAAAAAAAAAAAAB", "BAAAAAAAAAAAAAAAAAAAAAAAAAAAAAAAB", "BAAAAAAAAAAAAAAAAAAAAAAAAAAAAAAAB", "ABBBAAAAAAAAAAAAAAAAAAAAAAAAABBBA")
        .aisle("AABBBAAAAAAAAAAAAAAAAAAAAAAABBBAA", "AAAAAAAAAAAAAAAAAAAAAAAAAAAAAAAAA", "BAAAAAAAAAAAAAAAAAAAAAAAAAAAAAAAB", "BAAAAAAAAAAAAAAAAAAAAAAAAAAAAAAAB", "BAAAAAAAAAAAAAAAAAAAAAAAAAAAAAAAB", "AAAAAAAAAAAAAAAAAAAAAAAAAAAAAAAAA", "AAAAAAAAAAAAAAAAAAAAAAAAAAAAAAAAA", "AAAAAAAAAAAAAAAAAAAAAAAAAAAAAAAAA", "AAAAAAAAAAAAAAAAAAAAAAAAAAAAAAAAA", "AAAAAAAAAAAAAAAAAAAAAAAAAAAAAAAAA", "AAAAAAAAAAAAAAAAAAAAAAAAAAAAAAAAA", "AAAAAAAAAAAAAAAAAAAAAAAAAAAAAAAAA", "AAAAAAAAAAAAAAAAAAAAAAAAAAAAAAAAA", "AAAAAAAAAAAAAAAAAAAAAAAAAAAAAAAAA", "AAAAAAAAAAAAAAAAAAAAAAAAAAAAAAAAA", "AAAAAAAAAAAAAAAAAAAAAAAAAAAAAAAAA", "CAAAAAAAAAJJAAAAAAAAAJJAAAAAAAAAC", "AAAAAAAAAAAAAAAAAAAAAAAAAAAAAAAAA", "AAAAAAAAAAAAAAAAAAAAAAAAAAAAAAAAA", "AAAAAAAAAAAAAAAAAAAAAAAAAAAAAAAAA", "AAAAAAAAAAAAAAAAAAAAAAAAAAAAAAAAA", "AAAAAAAAAAAAAAAAAAAAAAAAAAAAAAAAA", "AAAAAAAAAAAAAAAAAAAAAAAAAAAAAAAAA", "AAAAAAAAAAAAAAAAAAAAAAAAAAAAAAAAA", "AAAAAAAAAAAAAAAAAAAAAAAAAAAAAAAAA", "AAAAAAAAAAAAAAAAAAAAAAAAAAAAAAAAA", "AAAAAAAAAAAAAAAAAAAAAAAAAAAAAAAAA", "AAAAAAAAAAAAAAAAAAAAAAAAAAAAAAAAA", "BAAAAAAAAAAAAAAAAAAAAAAAAAAAAAAAB", "BAAAAAAAAAAAAAAAAAAAAAAAAAAAAAAAB", "BAAAAAAAAAAAAAAAAAAAAAAAAAAAAAAAB", "AAAAAAAAAAAAAAAAAAAAAAAAAAAAAAAAA", "AABBBAAAAAAAAAAAAAAAAAAAAAAABBBAA")
        .aisle("AAABBBAAAAAAAAAAAAAAAAAAAAABBBAAA", "AAAAAAAAAAAAAAAAAAAAAAAAAAAAAAAAA", "AAAAAAAAAAAAAAAAAAAAAAAAAAAAAAAAA", "BAAAAAAAAAAAAAAAAAAAAAAAAAAAAAAAB", "BAAAAAAAAAAAAAAAAAAAAAAAAAAAAAAAB", "BAAAAAAAAAAAAAAAAAAAAAAAAAAAAAAAB", "AAAAAAAAAAAAAAAAAAAAAAAAAAAAAAAAA", "AAAAAAAAAAAAAAAAAAAAAAAAAAAAAAAAA", "AAAAAAAAAAAAAAAAAAAAAAAAAAAAAAAAA", "AAAAAAAAAAAAAAAAAAAAAAAAAAAAAAAAA", "AAAAAAAAAAAAAAAAAAAAAAAAAAAAAAAAA", "AAAAAAAAAAAAAAAAAAAAAAAAAAAAAAAAA", "AAAAAAAAAAAAAAAAAAAAAAAAAAAAAAAAA", "AAAAAAAAAAAAAAAAAAAAAAAAAAAAAAAAA", "AAAAAAAAAAAAAAAAAAAAAAAAAAAAAAAAA", "CAAAAAAAAAAAAAAAAAAAAAAAAAAAAAAAC", "CAAAAAAAAJJAAAAAAAAAAAJJAAAAAAAAC", "CAAAAAAAAAAAAAAAAAAAAAAAAAAAAAAAC", "AAAAAAAAAAAAAAAAAAAAAAAAAAAAAAAAA", "AAAAAAAAAAAAAAAAAAAAAAAAAAAAAAAAA", "AAAAAAAAAAAAAAAAAAAAAAAAAAAAAAAAA", "AAAAAAAAAAAAAAAAAAAAAAAAAAAAAAAAA", "AAAAAAAAAAAAAAAAAAAAAAAAAAAAAAAAA", "AAAAAAAAAAAAAAAAAAAAAAAAAAAAAAAAA", "AAAAAAAAAAAAAAAAAAAAAAAAAAAAAAAAA", "AAAAAAAAAAAAAAAAAAAAAAAAAAAAAAAAA", "AAAAAAAAAAAAAAAAAAAAAAAAAAAAAAAAA", "BAAAAAAAAAAAAAAAAAAAAAAAAAAAAAAAB", "BAAAAAAAAAAAAAAAAAAAAAAAAAAAAAAAB", "BAAAAAAAAAAAAAAAAAAAAAAAAAAAAAAAB", "AAAAAAAAAAAAAAAAAAAAAAAAAAAAAAAAA", "AAAAAAAAAAAAAAAAAAAAAAAAAAAAAAAAA", "AAABBBAAAAAAAAAAAAAAAAAAAAABBBAAA")
        .aisle("AAAABBBAAAAAAAAAAAAAAAAAAABBBAAAA", "AAAAAAAAAAAAAAAAAAAAAAAAAAAAAAAAA", "AAAAAAAAAAAAAAAAAAAAAAAAAAAAAAAAA", "AAAAAAAAAAAAAAAAAAAAAAAAAAAAAAAAA", "BAAAAAAAAAAAAAAAAAAAAAAAAAAAAAAAB", "BAAAAAAAAAAAAAAAAAAAAAAAAAAAAAAAB", "BAAAAAAAAAAAAAAAAAAAAAAAAAAAAAAAB", "AAAAAAAAAAAAAAAAAAAAAAAAAAAAAAAAA", "AAAAAAAAAAAAAAAAAAAAAAAAAAAAAAAAA", "AAAAAAAAAAAAAAAAAAAAAAAAAAAAAAAAA", "AAAAAAAAAAAAAAAAAAAAAAAAAAAAAAAAA", "AAAAAAAAAAAAAAAAAAAAAAAAAAAAAAAAA", "AAAAAAAAAAAAAAAAAAAAAAAAAAAAAAAAA", "AAAAAAAAAAAAAAAAAAAAAAAAAAAAAAAAA", "CAAAAAAAAAAAAAAAAAAAAAAAAAAAAAAAC", "CAAAAAAAAAAAAAAAAAAAAAAAAAAAAAAAC", "DAAAAAAAJJAAAAAAAAAAAAAJJAAAAAAAD", "CAAAAAAAAAAAAAAAAAAAAAAAAAAAAAAAC", "CAAAAAAAAAAAAAAAAAAAAAAAAAAAAAAAC", "AAAAAAAAAAAAAAAAAAAAAAAAAAAAAAAAA", "AAAAAAAAAAAAAAAAAAAAAAAAAAAAAAAAA", "AAAAAAAAAAAAAAAAAAAAAAAAAAAAAAAAA", "AAAAAAAAAAAAAAAAAAAAAAAAAAAAAAAAA", "AAAAAAAAAAAAAAAAAAAAAAAAAAAAAAAAA", "AAAAAAAAAAAAAAAAAAAAAAAAAAAAAAAAA", "AAAAAAAAAAAAAAAAAAAAAAAAAAAAAAAAA", "BAAAAAAAAAAAAAAAAAAAAAAAAAAAAAAAB", "BAAAAAAAAAAAAAAAAAAAAAAAAAAAAAAAB", "BAAAAAAAAAAAAAAAAAAAAAAAAAAAAAAAB", "AAAAAAAAAAAAAAAAAAAAAAAAAAAAAAAAA", "AAAAAAAAAAAAAAAAAAAAAAAAAAAAAAAAA", "AAAAAAAAAAAAAAAAAAAAAAAAAAAAAAAAA", "AAAABBBAAAAAAAAAAAAAAAAAAABBBAAAA")
        .aisle("AAAAABBBAAAAAAAACAAAAAAAABBBAAAAA", "AAAAAAAAAAAAAAAAAAAAAAAAAAAAAAAAA", "AAAAAAAAAAAAAAAAAAAAAAAAAAAAAAAAA", "AAAAAAAAAAAAAAAAAAAAAAAAAAAAAAAAA", "AAAAAAAAAAAAAAAAAAAAAAAAAAAAAAAAA", "BAAAAAAAAAAAAAAAAAAAAAAAAAAAAAAAB", "BAAAAAAAAAAAAAAAAAAAAAAAAAAAAAAAB", "BAAAAAAAAAAAAAAAAAAAAAAAAAAAAAAAB", "AAAAAAAAAAAAAAAAAAAAAAAAAAAAAAAAA", "AAAAAAAAAAAAAAAAAAAAAAAAAAAAAAAAA", "AAAAAAAAAAAAAAAAAAAAAAAAAAAAAAAAA", "AAAAAAAAAAAAAAAAAAAAAAAAAAAAAAAAA", "AAAAAAAAAAAAAAAAAAAAAAAAAAAAAAAAA", "CAAAAAAAAAAAAAAAAAAAAAAAAAAAAAAAC", "CAAAAAAAAAAAAAAAAAAAAAAAAAAAAAAAC", "EAAAAAAAAAAAAAAAAAAAAAAAAAAAAAAAE", "DAAAAAAJJAAAAAAJJJAAAAAAJJAAAAAAD", "EAAAAAAAAAAAAJJJJJJJAAAAAAAAAAAAE", "CAAAAAAAAAAAAAAJJJAAAAAAAAAAAAAAC", "CAAAAAAAAAAAAAAAAAAAAAAAAAAAAAAAC", "AAAAAAAAAAAAAAAAAAAAAAAAAAAAAAAAA", "AAAAAAAAAAAAAAAAAAAAAAAAAAAAAAAAA", "AAAAAAAAAAAAAAAAAAAAAAAAAAAAAAAAA", "AAAAAAAAAAAAAAAAAAAAAAAAAAAAAAAAA", "AAAAAAAAAAAAAAAAAAAAAAAAAAAAAAAAA", "BAAAAAAAAAAAAAAAAAAAAAAAAAAAAAAAB", "BAAAAAAAAAAAAAAAAAAAAAAAAAAAAAAAB", "BAAAAAAAAAAAAAAAAAAAAAAAAAAAAAAAB", "AAAAAAAAAAAAAAAAAAAAAAAAAAAAAAAAA", "AAAAAAAAAAAAAAAAAAAAAAAAAAAAAAAAA", "AAAAAAAAAAAAAAAAAAAAAAAAAAAAAAAAA", "AAAAAAAAAAAAAAAAAAAAAAAAAAAAAAAAA", "AAAAABBBAAAAAAAACAAAAAAAABBBAAAAA")
        .aisle("AAAAAABBBAAAAAACCCAAAAAABBBAAAAAA", "AAAAAAAAAAAAAAAAAAAAAAAAAAAAAAAAA", "AAAAAAAAAAAAAAAAAAAAAAAAAAAAAAAAA", "AAAAAAAAAAAAAAAAAAAAAAAAAAAAAAAAA", "AAAAAAAAAAAAAAAAAAAAAAAAAAAAAAAAA", "AAAAAAAAAAAAAAAAAAAAAAAAAAAAAAAAA", "BAAAAAAAAAAAAAAAAAAAAAAAAAAAAAAAB", "BAAAAAAAAAAAAAAAAAAAAAAAAAAAAAAAB", "BAAAAAAAAAAAAAAAAAAAAAAAAAAAAAAAB", "AAAAAAAAAAAAAAAAAAAAAAAAAAAAAAAAA", "AAAAAAAEEAAAAAAAAAAAAAAAEEAAAAAAA", "AAAAAAAEEAAAAAAAAAAAAAAAEEAAAAAAA", "CAAAAAAEEAAAAAAAAAAAAAAAEEAAAAAAC", "CAAAAAAEEAAAAAAAAAAAAAAAEEAAAAAAC", "FAAAAAAEEAAAAAAAAAAAAAAAEEAAAAAAF", "EAAAAAAEEAAAAAAAAAAAAAAAEEAAAAAAE", "DAAAAAJJEAAAJJJJJJJJJAAAEJJAAAAAD", "EAAAAAAEEAAJJJJJJJJJJJAAEEAAAAAAE", "FAAAAAAEEAAAJJJJJJJJJAAAEEAAAAAAF", "CAAAAAAEEAAAAAAAAAAAAAAAEEAAAAAAC", "CAAAAAAEEAAAAAAAAAAAAAAAEEAAAAAAC", "AAAAAAAEEAAAAAAAAAAAAAAAEEAAAAAAA", "AAAAAAAEEAAAAAAAAAAAAAAAEEAAAAAAA", "AAAAAAAAAAAAAAAAAAAAAAAAAAAAAAAAA", "BAAAAAAAAAAAAAAAAAAAAAAAAAAAAAAAB", "BAAAAAAAAAAAAAAAAAAAAAAAAAAAAAAAB", "BAAAAAAAAAAAAAAAAAAAAAAAAAAAAAAAB", "AAAAAAAAAAAAAAAAAAAAAAAAAAAAAAAAA", "AAAAAAAAAAAAAAAAAAAAAAAAAAAAAAAAA", "AAAAAAAAAAAAAAAAAAAAAAAAAAAAAAAAA", "AAAAAAAAAAAAAAAAAAAAAAAAAAAAAAAAA", "AAAAAAAAAAAAAAAAAAAAAAAAAAAAAAAAA", "AAAAAABBBAAAAAACCCAAAAAABBBAAAAAA")
        .aisle("AAAAAAABBBAAAACCDCCAAAABBBAAAAAAA", "AAAAAAAAAAAAAAAAAAAAAAAAAAAAAAAAA", "AAAAAAAAAAAAAAAAAAAAAAAAAAAAAAAAA", "AAAAAAAAAAAAAAAAAAAAAAAAAAAAAAAAA", "AAAAAAAAAAAAAAAAAAAAAAAAAAAAAAAAA", "AAAAAAAAAAAAAAAAAAAAAAAAAAAAAAAAA", "AAAAAAAAAAAAAAAAAAAAAAAAAAAAAAAAA", "BAAAAAAAAAAAAAAAAAAAAAAAAAAAAAAAB", "BAAAAAAAAAAAAAAAAAAAAAAAAAAAAAAAB", "BAAAAAAAEEAAAAAAAAAAAAAEEAAAAAAAB", "AAAAAAAEEAAAAAAAAAAAAAAAEEAAAAAAA", "CAAAAAAEEAAAAAAAAAAAAAAAEEAAAAAAC", "CAAAAAAEEAAAAAAAAAAAAAAAEEAAAAAAC", "FAAAAAAEEAAAAAAAAAAAAAAAEEAAAAAAF", "GAAAAAAEEAAAAAAAAAAAAAAAEEAAAAAAG", "EAAAAAAEEAAAAAAAAAAAAAAAEEAAAAAAE", "HAAAAJJEEAJJJJJJJJJJJJJAEEJJAAAAH", "EAAAAAAEEAJJJJJJJJJJJJJAEEAAAAAAE", "GAAAAAAEEAJJJJJJJJJJJJJAEEAAAAAAG", "FAAAAAAEEAAAAAAAAAAAAAAAEEAAAAAAF", "CAAAAAAEEAAAAAAAAAAAAAAAEEAAAAAAC", "CAAAAAAEEAAAAAAAAAAAAAAAEEAAAAAAC", "AAAAAAAEEAAAAAAAAAAAAAAAEEAAAAAAA", "BAAAAAAAEEAAAAAAAAAAAAAEEAAAAAAAB", "BAAAAAAAAAAAAAAAAAAAAAAAAAAAAAAAB", "BAAAAAAAAAAAAAAAAAAAAAAAAAAAAAAAB", "AAAAAAAAAAAAAAAAAAAAAAAAAAAAAAAAA", "AAAAAAAAAAAAAAAAAAAAAAAAAAAAAAAAA", "AAAAAAAAAAAAAAAAAAAAAAAAAAAAAAAAA", "AAAAAAAAAAAAAAAAAAAAAAAAAAAAAAAAA", "AAAAAAAAAAAAAAAAAAAAAAAAAAAAAAAAA", "AAAAAAAAAAAAAAAAAAAAAAAAAAAAAAAAA", "AAAAAAABBBAAAACCGCCAAAABBBAAAAAAA")
        .aisle("AAAAAAAABBBAACCEDECCAABBBAAAAAAAA", "AAAAAAAAAAAAAAAAAAAAAAAAAAAAAAAAA", "AAAAAAAAAAAAAAAAAAAAAAAAAAAAAAAAA", "AAAAAAAAAAAAAAAAAAAAAAAAAAAAAAAAA", "AAAAAAAAAAAAAAAAAAAAAAAAAAAAAAAAA", "AAAAAAAAAAAAAAAAAAAAAAAAAAAAAAAAA", "AAAAAAAAAAAAAAAAAAAAAAAAAAAAAAAAA", "AAAAAAAAAAAAAAAAAAAAAAAAAAAAAAAAA", "BAAAAAAAAEEAAAAAAAAAAAEEAAAAAAAAB", "BAAAAAAAEEAAAAAAAAAAAAAEEAAAAAAAB", "BAAAAAAAAAAAAAAAAAAAAAAAAAAAAAAAB", "CAAAAAAAAAAAAAAAAAAAAAAAAAAAAAAAC", "FAAAAAAAAAAAAAAAAAAAAAAAAAAAAAAAF", "IAAAAAAAAAAAAAAAAAAAAAAAAAAAAAAAI", "IAAAAAAAAAAAAAAAAAAAAAAAAAAAAAAAI", "EAAAAAAAAAAAAAAAAAAAAAAAAAAAAAAAE", "HAAAJJAAAJJJJAAAAAAAJJJJAAAJJAAAH", "EAAAAAAAAJJJJJAAKAAJJJJJAAAAAAAAE", "IAAAAAAAAJJJJAAAAAAAJJJJAAAAAAAAI", "IAAAAAAAAAAAAAAAAAAAAAAAAAAAAAAAI", "FAAAAAAAAAAAAAAAAAAAAAAAAAAAAAAAF", "CAAAAAAAAAAAAAAAAAAAAAAAAAAAAAAAC", "BAAAAAAAAAAAAAAAAAAAAAAAAAAAAAAAB", "BAAAAAAAEEAAAAAAAAAAAAAEEAAAAAAAB", "BAAAAAAAAEEAAAAAAAAAAAEEAAAAAAAAB", "AAAAAAAAAAAAAAAAAAAAAAAAAAAAAAAAA", "AAAAAAAAAAAAAAAAAAAAAAAAAAAAAAAAA", "AAAAAAAAAAAAAAAAAAAAAAAAAAAAAAAAA", "AAAAAAAAAAAAAAAAAAAAAAAAAAAAAAAAA", "AAAAAAAAAAAAAAAAAAAAAAAAAAAAAAAAA", "AAAAAAAAAAAAAAAAAAAAAAAAAAAAAAAAA", "AAAAAAAAAAAAAAAAAAAAAAAAAAAAAAAAA", "AAAAAAAABBBAACCEGECCAABBBAAAAAAAA")
        .aisle("AAAAAAAAABBBCCEEHEECCBBBAAAAAAAAA", "AAAAAAAAAAAAAAAAAAAAAAAAAAAAAAAAA", "AAAAAAAAAAAAAAAAAAAAAAAAAAAAAAAAA", "AAAAAAAAAAAAAAAAAAAAAAAAAAAAAAAAA", "AAAAAAAAAAAAAAAAAAAAAAAAAAAAAAAAA", "AAAAAAAAAAAAAAAAAAAAAAAAAAAAAAAAA", "AAAAAAAAAAAAAAAAAAAAAAAAAAAAAAAAA", "AAAAAAAAAAEEAAAAAAAAAEEAAAAAAAAAA", "AAAAAAAAAEEAAAAAAAAAAAEEAAAAAAAAA", "BAAAAAAAAAAAAAAAAAAAAAAAAAAAAAAAB", "BAAAAAAAAAAAAAAAAAAAAAAAAAAAAAAAB", "BAAAAAAAAAAAAAAAAAAAAAAAAAAAAAAAB", "FAAAAAAAAAAAAAAAAAAAAAAAAAAAAAAAF", "IAAAAAAAAAAAAAAAAAAAAAAAAAAAAAAAI", "IAAAAAAAAAAAAAAAAAAAAAAAAAAAAAAAI", "EAAAAAAAAAAAAAAAAAAAAAAAAAAAAAAAE", "HAAJJAAAJJJAAAAAKAAAAAJJJAAAJJAAH", "EAAAAAAAJJJJAAAKKKAAAJJJJAAAAAAAE", "IAAAAAAAJJJAAAAAKAAAAAJJJAAAAAAAI", "IAAAAAAAAAAAAAAAAAAAAAAAAAAAAAAAI", "FAAAAAAAAAAAAAAAAAAAAAAAAAAAAAAAF", "BAAAAAAAAAAAAAAAAAAAAAAAAAAAAAAAB", "BAAAAAAAAAAAAAAAAAAAAAAAAAAAAAAAB", "BAAAAAAAAAAAAAAAAAAAAAAAAAAAAAAAB", "AAAAAAAAAEEAAAAAAAAAAAEEAAAAAAAAA", "AAAAAAAAAAEEAAAAAAAAAEEAAAAAAAAAA", "AAAAAAAAAAAAAAAAAAAAAAAAAAAAAAAAA", "AAAAAAAAAAAAAAAAAAAAAAAAAAAAAAAAA", "AAAAAAAAAAAAAAAAAAAAAAAAAAAAAAAAA", "AAAAAAAAAAAAAAAAAAAAAAAAAAAAAAAAA", "AAAAAAAAAAAAAAAAAAAAAAAAAAAAAAAAA", "AAAAAAAAAAAAAAAAAAAAAAAAAAAAAAAAA", "AAAAAAAAABBBCCEEHEECCBBBAAAAAAAAA")
        .aisle("AAAAAAAAAABBBDDHHHDDBBBAAAAAAAAAA", "AAAAAAAAAAAAAAAAAAAAAAAAAAAAAAAAA", "AAAAAAAAAAAAAAAAAAAAAAAAAAAAAAAAA", "AAAAAAAAAAAAAAAAAAAAAAAAAAAAAAAAA", "AAAAAAAAAAAAAAAAAAAAAAAAAAAAAAAAA", "AAAAAAAAAAAAAAAAAAAAAAAAAAAAAAAAA", "AAAAAAAAAAAEEAAAAAAAEEAAAAAAAAAAA", "AAAAAAAAAAEEAAAAAAAAAEEAAAAAAAAAA", "CAAAAAAAAAAAAAAAAAAAAAAAAAAAAAAAC", "CAAAAAAAAAAAAAAAAAAAAAAAAAAAAAAAC", "BAAAAAAAAAAAAAAAAAAAAAAAAAAAAAAAB", "BAAAAAAAAAAAAAAAAAAAAAAAAAAAAAAAB", "BAAAAAAAAAAAAAAAAAAAAAAAAAAAAAAAB", "FAAAAAAAAAAAAAAAAAAAAAAAAAAAAAAAF", "GAAAAAAAAAAAAAAAAAAAAAAAAAAAAAAAG", "EAAAAAAAAAAAAAALLLAAAAAAAAAAAAAAE", "HAJJAAAAJJAAAALLLLLAAAAJJAAAAJJAH", "EAAAAAAJJJJAAALLLLLAAAJJJJAAAAAAE", "GAAAAAAAJJAAAALLLLLAAAAJJAAAAAAAG", "FAAAAAAAAAAAAAALLLAAAAAAAAAAAAAAF", "BAAAAAAAAAAAAAAAAAAAAAAAAAAAAAAAB", "BAAAAAAAAAAAAAAAAAAAAAAAAAAAAAAAB", "BAAAAAAAAAAAAAAAAAAAAAAAAAAAAAAAB", "CAAAAAAAAAAAAAAAAAAAAAAAAAAAAAAAC", "CAAAAAAAAAAAAAAAAAAAAAAAAAAAAAAAC", "AAAAAAAAAAEEAAAAAAAAAEEAAAAAAAAAA", "AAAAAAAAAAAEEAAAAAAAEEAAAAAAAAAAA", "AAAAAAAAAAAAAAAAAAAAAAAAAAAAAAAAA", "AAAAAAAAAAAAAAAAAAAAAAAAAAAAAAAAA", "AAAAAAAAAAAAAAAAAAAAAAAAAAAAAAAAA", "AAAAAAAAAAAAAAAAAAAAAAAAAAAAAAAAA", "AAAAAAAAAAAAAAAAAAAAAAAAAAAAAAAAA", "AAAAAAAAAABBBGGHHHGGBBBAAAAAAAAAA")
        .aisle("AAAAAAAAAACBBBEEHEEBBBCAAAAAAAAAA", "AAAAAAAAAAAAAAAAAAAAAAAAAAAAAAAAA", "AAAAAAAAAAAAAAAAAAAAAAAAAAAAAAAAA", "AAAAAAAAAAAAAAAAAAAAAAAAAAAAAAAAA", "AAAAAAAAAAAAAAAAAAAAAAAAAAAAAAAAA", "AAAAAAAAAAAAEEAAAAAEEAAAAAAAAAAAA", "AAAAAAAAAAAEEAAAAAAAEEAAAAAAAAAAA", "CAAAAAAAAAAAAAAAAAAAAAAAAAAAAAAAC", "CAAAAAAAAAAAAAAAAAAAAAAAAAAAAAAAC", "FAAAAAAAAAAAAAAAAAAAAAAAAAAAAAAAF", "FAAAAAAAAAAAAAAAAAAAAAAAAAAAAAAAF", "BAAAAAAAAAAAAAAAAAAAAAAAAAAAAAAAB", "BAAAAAAAAAAAAAAAAAAAAAAAAAAAAAAAB", "BAAAAAAAAAAAAAKAAAKAAAAAAAAAAAAAB", "FAAAAAAAAAAAAKLLLLLKAAAAAAAAAAAAF", "EAAAAAAAAAAAALLAAALLAAAAAAAAAAAAE", "GJJAAAAJJJAAALAMMMALAAAJJJAAAAJJG", "EAAAAAAJJJAAALAMMMALAAAJJJAAAAAAE", "FAAAAAAJJJAAALAMMMALAAAJJJAAAAAAF", "BAAAAAAAAAAAALLAAALLAAAAAAAAAAAAB", "BAAAAAAAAAAAAKLLLLLKAAAAAAAAAAAAB", "BAAAAAAAAAAAAAAAAAAAAAAAAAAAAAAAB", "FAAAAAAAAAAAAAAAAAAAAAAAAAAAAAAAF", "FAAAAAAAAAAAAAAAAAAAAAAAAAAAAAAAF", "CAAAAAAAAAAAAAAAAAAAAAAAAAAAAAAAC", "CAAAAAAAAAAAAAAAAAAAAAAAAAAAAAAAC", "AAAAAAAAAAAEEAAAAAAAEEAAAAAAAAAAA", "AAAAAAAAAAAAEEAAAAAEEAAAAAAAAAAAA", "AAAAAAAAAAAAAAAAAAAAAAAAAAAAAAAAA", "AAAAAAAAAAAAAAAAAAAAAAAAAAAAAAAAA", "AAAAAAAAAAAAAAAAAAAAAAAAAAAAAAAAA", "AAAAAAAAAAAAAAAAAAAAAAAAAAAAAAAAA", "AAAAAAAAAACBBBEEHEEBBBCAAAAAAAAAA")
        .aisle("AAAAAAAAACCDBBBEGEBBBDCCAAAAAAAAA", "AAAAAAAAAAAAAAAAAAAAAAAAAAAAAAAAA", "AAAAAAAAAAAAAAAAAAAAAAAAAAAAAAAAA", "AAAAAAAAAAAAAAAAAAAAAAAAAAAAAAAAA", "AAAAAAAAAAAAAEEAAAEEAAAAAAAAAAAAA", "AAAAAAAAAAAAEEAAAAAEEAAAAAAAAAAAA", "CAAAAAAAAAAAAKAAAAAKAAAAAAAAAAAAC", "CAAAAAAAAAAAAAAAAAAAAAAAAAAAAAAAC", "FAAAAAAAAAAAAAAAAAAAAAAAAAAAAAAAF", "IAAAAAAAAAAAAAAAAAAAAAAAAAAAAAAAI", "IAAAAAAAAAAAAAAAAAAAAAAAAAAAAAAAI", "FAAAAAAAAAAAAAAAAAAAAAAAAAAAAAAAF", "BAAAAAAAAAAAAAAKAKAAAAAAAAAAAAAAB", "BAAAAAAAAAAAAKLLLLLKAAAAAAAAAAAAB", "BAAAAAAAAAAAKLNAAANLKAAAAAAAAAAAB", "EGAAAAAAAAAALKAAAAAKLAAAAAAAAAAGE", "GJAAAAAJJAAALKAAAAAKLAAAJJAAAAAJG", "EGAAAAJJJJAALKAAKAAKLAAJJJJAAAAGE", "BAAAAAAJJAAALKAAAAAKLAAAJJAAAAAAB", "BAAAAAAAAAAALKAAAAAKLAAAAAAAAAAAB", "BAAAAAAAAAAAKLNAAANLKAAAAAAAAAAAB", "FAAAAAAAAAAAAKLLLLLKAAAAAAAAAAAAF", "IAAAAAAAAAAAAAKAAAKAAAAAAAAAAAAAI", "IAAAAAAAAAAAAAAAAAAAAAAAAAAAAAAAI", "FAAAAAAAAAAAAAAAAAAAAAAAAAAAAAAAF", "CAAAAAAAAAAAAAAAAAAAAAAAAAAAAAAAC", "CAAAAAAAAAAAAAKAAAKAAAAAAAAAAAAAC", "AAAAAAAAAAAAEEAAAAAEEAAAAAAAAAAAA", "AAAAAAAAAAAAAEEAAAEEAAAAAAAAAAAAA", "AAAAAAAAAAAAAAAAAAAAAAAAAAAAAAAAA", "AAAAAAAAAAAAAAAAAAAAAAAAAAAAAAAAA", "AAAAAAAAAAAAAAAAAAAAAAAAAAAAAAAAA", "AAAAAAAAACCGBBBEGEBBBGCCAAAAAAAAA")
        .aisle("AAAAAAAACCEDEBBBGBBBEDECCAAAAAAAA", "AAAAAAAAAAAAAACCCCCAAAAAAAAAAAAAA", "AAAAAAAAAAAAAAAAAAAAAAAAAAAAAAAAA", "AAAAAAAAAAAAAAEEAEEAAAAAAAAAAAAAA", "AAAAAAAAAAAAAEEAAAEEAAAAAAAAAAAAA", "CAAAAAAAAAAAAAAAAAAAAAAAAAAAAAAAC", "CAAAAAAAAAAAAAKAAAKAAAAAAAAAAAAAC", "FAAAAAAAAAAAAAAAAAAAAAAAAAAAAAAAF", "GAAAAAAAAAAAAAAAAAAAAAAAAAAAAAAAG", "IAAAAAAAAAAAAAAAAAAAAAAAAAAAAAAAI", "IAAAAAAAAAAAAAAAAAAAAAAAAAAAAAAAI", "GAAAAAAAAAAAAAAKAKAAAAAAAAAAAAAAG", "FAAAAAAAAAAAAAKLLLKAAAAAAAAAAAAAF", "BAAAAAAAAAAAKLLAAALLKAAAAAAAAAAAB", "BAAAAAAAAAAALNKAAAKNLAAAAAAAAAAAB", "BGAAAAAAAAAALAAAAAAALAAAAAAAAAAGB", "GGAAAAAJJAALAAAAAAAAALAAJJAAAAAGG", "BGAAAAJJJAALAAAAKAAAALAAJJJAAAAGB", "BAAAAAAJJAALAAAAAAAAALAAJJAAAAAAB", "BAAAAAAAAAAALAAAAAAALAAAAAAAAAAAB", "FAAAAAAAAAAALNKAAAKNLAAAAAAAAAAAF", "GAAAAAAAAAAAALLAAALLAAAAAAAAAAAAG", "IAAAAAAAAAAAAKKLLLKKAAAAAAAAAAAAI", "IAAAAAAAAAAAAAAKAKAAAAAAAAAAAAAAI", "GAAAAAAAAAAAAAAAAAAAAAAAAAAAAAAAG", "FAAAAAAAAAAAAAAAAAAAAAAAAAAAAAAAF", "CAAAAAAAAAAAAAAKAKAAAAAAAAAAAAAAC", "CAAAAAAAAAAAAAAAKAAAAAAAAAAAAAAAC", "AAAAAAAAAAAAAEEKKKEEAAAAAAAAAAAAA", "AAAAAAAAAAAAAAEEAEEAAAAAAAAAAAAAA", "AAAAAAAAAAAAAAAAAAAAAAAAAAAAAAAAA", "AAAAAAAAAAAAAACCCCCAAAAAAAAAAAAAA", "AAAAAAAACCEGEBBBGBBBEGECCAAAAAAAA")
        .aisle("AAAAAAACCEEHEEBBBBBEEHEECCAAAAAAA", "AAAAAAAAAAAAAACGGGCAAAAAAAAAAAAAA", "AAAAAAAAAAAAAAAEEEAAAAAAAAAAAAAAA", "AAAAAAAAAAAAAAEEKEEAAAAAAAAAAAAAA", "CAAAAAAAAAAAAAAAAAAAAAAAAAAAAAAAC", "CAAAAAAAAAAAAAAAAAAAAAAAAAAAAAAAC", "EAAAAAAAAAAAAAAKKKAAAAAAAAAAAAAAE", "EAAAAAAAAAAAAAAOOOAAAAAAAAAAAAAAE", "EAAAAAAAAAAAAAAKKKAAAAAAAAAAAAAAE", "EAAAAAAAAAAAAAAAAAAAAAAAAAAAAAAAE", "EAAAAAAAAAAAAAAAAAAAAAAAAAAAAAAAE", "EAAAAAAAAAAAAAKGGGKAAAAAAAAAAAAAE", "EAAAAAAAAAAAAKLLLLLKAAAAAAAAAAAAE", "EAAAAAAAAAAAALAMMMALAAAAAAAAAAAAE", "BAAAAAAAAAAALAAAAAAALAAAAAAAAAAAB", "BGAAAAAAAAALAAAAPAAAALAAAAAAAAAGB", "BGAAAAJJJAALMAAPAPAAMLAAJJJAAAAGB", "BGAAAAJJJAKLMAAAKAAAMLKAJJJAAAAGB", "BAAAAAJJJAALMAAPAPAAMLAAJJJAAAAAB", "EAAAAAAAAAALAAAAPAAAALAAAAAAAAAAE", "EAAAAAAAAAAALAAAAAAALAAAAAAAAAAAE", "EAAAAAAAAAAAALAMMMALAAAAAAAAAAAAE", "EAAAAAAAAAAAAALLLLLAAAAAAAAAAAAAE", "EAAAAAAAAAAAAAKGGGKAAAAAAAAAAAAAE", "EAAAAAAAAAAAAAAAAAAAAAAAAAAAAAAAE", "EAAAAAAAAAAAAAAAAAAAAAAAAAAAAAAAE", "EAAAAAAAAAAAAAAAKAAAAAAAAAAAAAAAE", "CAAAAAAAAAAAAAAAAAAAAAAAAAAAAAAAC", "CAAAAAAAAAAAAAKAAAKAAAAAAAAAAAAAC", "AAAAAAAAAAAAAAEEKEEAAAAAAAAAAAAAA", "AAAAAAAAAAAAAAAEEEAAAAAAAAAAAAAAA", "AAAAAAAAAAAAAACGGGCAAAAAAAAAAAAAA", "AAAAAAACCEEHEEBBBBBEEHEECCAAAAAAA")
        .aisle("AAAAAACCDDHHHGGBBBGGHHHDDCCAAAAAA", "AAAAAAAAAAAAAACGGGCAAAAAAAAAAAAAA", "AAAAAAAAAAAAAAAEEEAAAAAAAAAAAAAAA", "CAAAAAAAAAAAAAAKQKAAAAAAAAAAAAAAC", "CAAAAAAAAAAAAAAAKAAAAAAAAAAAAAAAC", "DAAAAAAAAAAAAAAAKAAAAAAAAAAAAAAAD", "DAAAAAAAAAAAAAAKKKAAAAAAAAAAAAAAD", "DAAAAAAAAAAAAAAOOOAAAAAAAAAAAAAAD", "HAAAAAAAAAAAAAAKKKAAAAAAAAAAAAAAH", "HAAAAAAAAAAAAAAAKAAAAAAAAAAAAAAAH", "HAAAAAAAAAAAAAAAKAAAAAAAAAAAAAAAH", "HAAAAAAAAAAAAAAGQGAAAAAAAAAAAAAAH", "GAAAAAAAAAAAAALLLLLAAAAAAAAAAAAAG", "GAAAAAAAAAAAALAMMMALAAAAAAAAAAAAG", "GAAAAAAAAAAALAAAKAAALAAAAAAAAAAAG", "BGAAAAAGAAALAAAPKPAAALAAAAAAAAAGB", "BGAAAAJJJAKLMAAAKAAAMLKAJJJAAAAGB", "BGAAAAJJJKKLMKKKRKKKMLKKJJJAAAAGB", "GAAAAAJJJAKLMAAAKAAAMLKAJJJAAAAAG", "GAAAAAAAAAALAAAPKPAAALAAAAAAAAAAG", "GAAAAAAAAAAALAAAKAAALAAAAAAAAAAAG", "HAAAAAAAAAAAALAMMMALAAAAAAAAAAAAH", "HAAAAAAAAAAAAALLLLLAAAAAAAAAAAAAH", "HAAAAAAAAAAAAAAGQGAAAAAAAAAAAAAAH", "HAAAAAAAAAAAAAAAKAAAAAAAAAAAAAAAH", "DAAAAAAAAAAAAAAAKAAAAAAAAAAAAAAAD", "DAAAAAAAAAAAAAAKKKAAAAAAAAAAAAAAD", "DAAAAAAAAAAAAAKAKAKAAAAAAAAAAAAAD", "CAAAAAAAAAAAAAKAKAKAAAAAAAAAAAAAC", "CAAAAAAAAAAAAAAKQKAAAAAAAAAAAAAAC", "AAAAAAAAAAAAAAAEEEAAAAAAAAAAAAAAA", "AAAAAAAAAAAAAACGGGCAAAAAAAAAAAAAA", "AAAAAACCGGHHHGGBBBGGHHHGGCCAAAAAA")
        .aisle("AAAAAAACCEEHEEBBBBBEEHEECCAAAAAAA", "AAAAAAAAAAAAAACGGGCAAAAAAAAAAAAAA", "AAAAAAAAAAAAAAAEEEAAAAAAAAAAAAAAA", "AAAAAAAAAAAAAAEEKEEAAAAAAAAAAAAAA", "CAAAAAAAAAAAAAAAAAAAAAAAAAAAAAAAC", "CAAAAAAAAAAAAAAAAAAAAAAAAAAAAAAAC", "EAAAAAAAAAAAAAAKKKAAAAAAAAAAAAAAE", "EAAAAAAAAAAAAAAOOOAAAAAAAAAAAAAAE", "EAAAAAAAAAAAAAAKKKAAAAAAAAAAAAAAE", "EAAAAAAAAAAAAAAAAAAAAAAAAAAAAAAAE", "EAAAAAAAAAAAAAAAAAAAAAAAAAAAAAAAE", "EAAAAAAAAAAAAAKGGGKAAAAAAAAAAAAAE", "EAAAAAAAAAAAAKLLLLLKAAAAAAAAAAAAE", "EAAAAAAAAAAAALAMMMALAAAAAAAAAAAAE", "BAAAAAAAAAAALAAAAAAALAAAAAAAAAAAB", "BGAAAAAAAAALAAAAPAAAALAAAAAAAAAGB", "BGAAAAJJJAALMAAPAPAAMLAAJJJAAAAGB", "BGAAAAJJJAKLMAAAKAAAMLKAJJJAAAAGB", "BAAAAAJJJAALMAAPAPAAMLAAJJJAAAAAB", "EAAAAAAAAAALAAAAPAAAALAAAAAAAAAAE", "EAAAAAAAAAAALAAAAAAALAAAAAAAAAAAE", "EAAAAAAAAAAAALAMMMALAAAAAAAAAAAAE", "EAAAAAAAAAAAAALLLLLAAAAAAAAAAAAAE", "EAAAAAAAAAAAAAKGGGKAAAAAAAAAAAAAE", "EAAAAAAAAAAAAAAAAAAAAAAAAAAAAAAAE", "EAAAAAAAAAAAAAAAAAAAAAAAAAAAAAAAE", "EAAAAAAAAAAAAAAAKAAAAAAAAAAAAAAAE", "CAAAAAAAAAAAAAAAAAAAAAAAAAAAAAAAC", "CAAAAAAAAAAAAAKAKAKAAAAAAAAAAAAAC", "AAAAAAAAAAAAAAEEKEEAAAAAAAAAAAAAA", "AAAAAAAAAAAAAAAEEEAAAAAAAAAAAAAAA", "AAAAAAAAAAAAAACGGGCAAAAAAAAAAAAAA", "AAAAAAACCEEHEEBBBBBEEHEECCAAAAAAA")
        .aisle("AAAAAAAACCEDEBBBGBBBEDECCAAAAAAAA", "AAAAAAAAAAAAAACCCCCAAAAAAAAAAAAAA", "AAAAAAAAAAAAAAAAAAAAAAAAAAAAAAAAA", "AAAAAAAAAAAAAAEEAEEAAAAAAAAAAAAAA", "AAAAAAAAAAAAAEEAAAEEAAAAAAAAAAAAA", "CAAAAAAAAAAAAAAAAAAAAAAAAAAAAAAAC", "CAAAAAAAAAAAAAKAAAKAAAAAAAAAAAAAC", "FAAAAAAAAAAAAAAAAAAAAAAAAAAAAAAAF", "GAAAAAAAAAAAAAAAAAAAAAAAAAAAAAAAG", "IAAAAAAAAAAAAAAAAAAAAAAAAAAAAAAAI", "IAAAAAAAAAAAAAAAAAAAAAAAAAAAAAAAI", "GAAAAAAAAAAAAAAKAKAAAAAAAAAAAAAAG", "FAAAAAAAAAAAAAKLLLKAAAAAAAAAAAAAF", "BAAAAAAAAAAAKLLAAALLKAAAAAAAAAAAB", "BAAAAAAAAAAALNKAAAKNLAAAAAAAAAAAB", "BGAAAAAAAAAALAAAAAAALAAAAAAAAAAGB", "GGAAAAAJJAALAAAAAAAAALAAJJAAAAAGG", "BGAAAAJJJAALAAAAKAAAALAAJJJAAAAGB", "BAAAAAAJJAALAAAAAAAAALAAJJAAAAAAB", "BAAAAAAAAAAALAAAAAAALAAAAAAAAAAAB", "FAAAAAAAAAAALNKAAAKNLAAAAAAAAAAAF", "GAAAAAAAAAAAALLAAALLAAAAAAAAAAAAG", "IAAAAAAAAAAAAKKLLLKKAAAAAAAAAAAAI", "IAAAAAAAAAAAAAAKAKAAAAAAAAAAAAAAI", "GAAAAAAAAAAAAAAAAAAAAAAAAAAAAAAAG", "FAAAAAAAAAAAAAAAAAAAAAAAAAAAAAAAF", "CAAAAAAAAAAAAAAKAKAAAAAAAAAAAAAAC", "CAAAAAAAAAAAAAAAKAAAAAAAAAAAAAAAC", "AAAAAAAAAAAAAEEKKKEEAAAAAAAAAAAAA", "AAAAAAAAAAAAAAEEAEEAAAAAAAAAAAAAA", "AAAAAAAAAAAAAAAAAAAAAAAAAAAAAAAAA", "AAAAAAAAAAAAAACCCCCAAAAAAAAAAAAAA", "AAAAAAAACCEGEBBBGBBBEGECCAAAAAAAA")
        .aisle("AAAAAAAAACCDBBBEGEBBBDCCAAAAAAAAA", "AAAAAAAAAAAAAAAAAAAAAAAAAAAAAAAAA", "AAAAAAAAAAAAAAAAAAAAAAAAAAAAAAAAA", "AAAAAAAAAAAAAAAAAAAAAAAAAAAAAAAAA", "AAAAAAAAAAAAAEEAAAEEAAAAAAAAAAAAA", "AAAAAAAAAAAAEEAAAAAEEAAAAAAAAAAAA", "CAAAAAAAAAAAAKAAAAAKAAAAAAAAAAAAC", "CAAAAAAAAAAAAAAAAAAAAAAAAAAAAAAAC", "FAAAAAAAAAAAAAAAAAAAAAAAAAAAAAAAF", "IAAAAAAAAAAAAAAAAAAAAAAAAAAAAAAAI", "IAAAAAAAAAAAAAAAAAAAAAAAAAAAAAAAI", "FAAAAAAAAAAAAAAAAAAAAAAAAAAAAAAAF", "BAAAAAAAAAAAAAAKAKAAAAAAAAAAAAAAB", "BAAAAAAAAAAAAKLLLLLKAAAAAAAAAAAAB", "BAAAAAAAAAAAKLNAAANLKAAAAAAAAAAAB", "EGAAAAAAAAAALKAAAAAKLAAAAAAAAAAGE", "GJAAAAAJJAAALKAAAAAKLAAAJJAAAAAJG", "EGAAAAJJJJAALKAAKAAKLAAJJJJAAAAGE", "BAAAAAAJJAAALKAAAAAKLAAAJJAAAAAAB", "BAAAAAAAAAAALKAAAAAKLAAAAAAAAAAAB", "BAAAAAAAAAAAKLNAAANLKAAAAAAAAAAAB", "FAAAAAAAAAAAAKLLLLLKAAAAAAAAAAAAF", "IAAAAAAAAAAAAAKAAAKAAAAAAAAAAAAAI", "IAAAAAAAAAAAAAAAAAAAAAAAAAAAAAAAI", "FAAAAAAAAAAAAAAAAAAAAAAAAAAAAAAAF", "CAAAAAAAAAAAAAAAAAAAAAAAAAAAAAAAC", "CAAAAAAAAAAAAAKAAAKAAAAAAAAAAAAAC", "AAAAAAAAAAAAEEAAAAAEEAAAAAAAAAAAA", "AAAAAAAAAAAAAEEAAAEEAAAAAAAAAAAAA", "AAAAAAAAAAAAAAAAAAAAAAAAAAAAAAAAA", "AAAAAAAAAAAAAAAAAAAAAAAAAAAAAAAAA", "AAAAAAAAAAAAAAAAAAAAAAAAAAAAAAAAA", "AAAAAAAAACCGBBBEGEBBBGCCAAAAAAAAA")
        .aisle("AAAAAAAAAACBBBEEHEEBBBCAAAAAAAAAA", "AAAAAAAAAAAAAAAAAAAAAAAAAAAAAAAAA", "AAAAAAAAAAAAAAAAAAAAAAAAAAAAAAAAA", "AAAAAAAAAAAAAAAAAAAAAAAAAAAAAAAAA", "AAAAAAAAAAAAAAAAAAAAAAAAAAAAAAAAA", "AAAAAAAAAAAAEEAAAAAEEAAAAAAAAAAAA", "AAAAAAAAAAAEEAAAAAAAEEAAAAAAAAAAA", "CAAAAAAAAAAAAAAAAAAAAAAAAAAAAAAAC", "CAAAAAAAAAAAAAAAAAAAAAAAAAAAAAAAC", "FAAAAAAAAAAAAAAAAAAAAAAAAAAAAAAAF", "FAAAAAAAAAAAAAAAAAAAAAAAAAAAAAAAF", "BAAAAAAAAAAAAAAAAAAAAAAAAAAAAAAAB", "BAAAAAAAAAAAAAAAAAAAAAAAAAAAAAAAB", "BAAAAAAAAAAAAAKAAAKAAAAAAAAAAAAAB", "FAAAAAAAAAAAAKLLLLLKAAAAAAAAAAAAF", "EAAAAAAAAAAAALLAAALLAAAAAAAAAAAAE", "GJJAAAAJJJAAALAMMMALAAAJJJAAAAJJG", "EAAAAAAJJJAAALAMMMALAAAJJJAAAAAAE", "FAAAAAAJJJAAALAMMMALAAAJJJAAAAAAF", "BAAAAAAAAAAAALLAAALLAAAAAAAAAAAAB", "BAAAAAAAAAAAAKLLLLLKAAAAAAAAAAAAB", "BAAAAAAAAAAAAAAAAAAAAAAAAAAAAAAAB", "FAAAAAAAAAAAAAAAAAAAAAAAAAAAAAAAF", "FAAAAAAAAAAAAAAAAAAAAAAAAAAAAAAAF", "CAAAAAAAAAAAAAAAAAAAAAAAAAAAAAAAC", "CAAAAAAAAAAAAAAAAAAAAAAAAAAAAAAAC", "AAAAAAAAAAAEEAAAAAAAEEAAAAAAAAAAA", "AAAAAAAAAAAAEEAAAAAEEAAAAAAAAAAAA", "AAAAAAAAAAAAAAAAAAAAAAAAAAAAAAAAA", "AAAAAAAAAAAAAAAAAAAAAAAAAAAAAAAAA", "AAAAAAAAAAAAAAAAAAAAAAAAAAAAAAAAA", "AAAAAAAAAAAAAAAAAAAAAAAAAAAAAAAAA", "AAAAAAAAAACBBBEEHEEBBBCAAAAAAAAAA")
        .aisle("AAAAAAAAAABBBDDHHHDDBBBAAAAAAAAAA", "AAAAAAAAAAAAAAAAAAAAAAAAAAAAAAAAA", "AAAAAAAAAAAAAAAAAAAAAAAAAAAAAAAAA", "AAAAAAAAAAAAAAAAAAAAAAAAAAAAAAAAA", "AAAAAAAAAAAAAAAAAAAAAAAAAAAAAAAAA", "AAAAAAAAAAAAAAAAAAAAAAAAAAAAAAAAA", "AAAAAAAAAAAEEAAAAAAAEEAAAAAAAAAAA", "AAAAAAAAAAEEAAAAAAAAAEEAAAAAAAAAA", "CAAAAAAAAAAAAAAAAAAAAAAAAAAAAAAAC", "CAAAAAAAAAAAAAAAAAAAAAAAAAAAAAAAC", "BAAAAAAAAAAAAAAAAAAAAAAAAAAAAAAAB", "BAAAAAAAAAAAAAAAAAAAAAAAAAAAAAAAB", "BAAAAAAAAAAAAAAAAAAAAAAAAAAAAAAAB", "FAAAAAAAAAAAAAAAAAAAAAAAAAAAAAAAF", "GAAAAAAAAAAAAAAAAAAAAAAAAAAAAAAAG", "EAAAAAAAAAAAAAALLLAAAAAAAAAAAAAAE", "HAJJAAAAJJAAAALLLLLAAAAJJAAAAJJAH", "EAAAAAAJJJJAAALLLLLAAAJJJJAAAAAAE", "GAAAAAAAJJAAAALLLLLAAAAJJAAAAAAAG", "FAAAAAAAAAAAAAALLLAAAAAAAAAAAAAAF", "BAAAAAAAAAAAAAAAAAAAAAAAAAAAAAAAB", "BAAAAAAAAAAAAAAAAAAAAAAAAAAAAAAAB", "BAAAAAAAAAAAAAAAAAAAAAAAAAAAAAAAB", "CAAAAAAAAAAAAAAAAAAAAAAAAAAAAAAAC", "CAAAAAAAAAAAAAAAAAAAAAAAAAAAAAAAC", "AAAAAAAAAAEEAAAAAAAAAEEAAAAAAAAAA", "AAAAAAAAAAAEEAAAAAAAEEAAAAAAAAAAA", "AAAAAAAAAAAAAAAAAAAAAAAAAAAAAAAAA", "AAAAAAAAAAAAAAAAAAAAAAAAAAAAAAAAA", "AAAAAAAAAAAAAAAAAAAAAAAAAAAAAAAAA", "AAAAAAAAAAAAAAAAAAAAAAAAAAAAAAAAA", "AAAAAAAAAAAAAAAAAAAAAAAAAAAAAAAAA", "AAAAAAAAAABBBGGHHHGGBBBAAAAAAAAAA")
        .aisle("AAAAAAAAABBBCCEEHEECCBBBAAAAAAAAA", "AAAAAAAAAAAAAAAAAAAAAAAAAAAAAAAAA", "AAAAAAAAAAAAAAAAAAAAAAAAAAAAAAAAA", "AAAAAAAAAAAAAAAAAAAAAAAAAAAAAAAAA", "AAAAAAAAAAAAAAAAAAAAAAAAAAAAAAAAA", "AAAAAAAAAAAAAAAAAAAAAAAAAAAAAAAAA", "AAAAAAAAAAAAAAAAAAAAAAAAAAAAAAAAA", "AAAAAAAAAAEEAAAAAAAAAEEAAAAAAAAAA", "AAAAAAAAAEEAAAAAAAAAAAEEAAAAAAAAA", "BAAAAAAAAAAAAAAAAAAAAAAAAAAAAAAAB", "BAAAAAAAAAAAAAAAAAAAAAAAAAAAAAAAB", "BAAAAAAAAAAAAAAAAAAAAAAAAAAAAAAAB", "FAAAAAAAAAAAAAAAAAAAAAAAAAAAAAAAF", "IAAAAAAAAAAAAAAAAAAAAAAAAAAAAAAAI", "IAAAAAAAAAAAAAAAAAAAAAAAAAAAAAAAI", "EAAAAAAAAAAAAAAAAAAAAAAAAAAAAAAAE", "HAAJJAAAJJJAAAAAKAAAAAJJJAAAJJAAH", "EAAAAAAAJJJJAAAKKKAAAJJJJAAAAAAAE", "IAAAAAAAJJJAAAAAKAAAAAJJJAAAAAAAI", "IAAAAAAAAAAAAAAAAAAAAAAAAAAAAAAAI", "FAAAAAAAAAAAAAAAAAAAAAAAAAAAAAAAF", "BAAAAAAAAAAAAAAAAAAAAAAAAAAAAAAAB", "BAAAAAAAAAAAAAAAAAAAAAAAAAAAAAAAB", "BAAAAAAAAAAAAAAAAAAAAAAAAAAAAAAAB", "AAAAAAAAAEEAAAAAAAAAAAEEAAAAAAAAA", "AAAAAAAAAAEEAAAAAAAAAEEAAAAAAAAAA", "AAAAAAAAAAAAAAAAAAAAAAAAAAAAAAAAA", "AAAAAAAAAAAAAAAAAAAAAAAAAAAAAAAAA", "AAAAAAAAAAAAAAAAAAAAAAAAAAAAAAAAA", "AAAAAAAAAAAAAAAAAAAAAAAAAAAAAAAAA", "AAAAAAAAAAAAAAAAAAAAAAAAAAAAAAAAA", "AAAAAAAAAAAAAAAAAAAAAAAAAAAAAAAAA", "AAAAAAAAABBBCCEEHEECCBBBAAAAAAAAA")
        .aisle("AAAAAAAABBBAACCEDECCAABBBAAAAAAAA", "AAAAAAAAAAAAAAAAAAAAAAAAAAAAAAAAA", "AAAAAAAAAAAAAAAAAAAAAAAAAAAAAAAAA", "AAAAAAAAAAAAAAAAAAAAAAAAAAAAAAAAA", "AAAAAAAAAAAAAAAAAAAAAAAAAAAAAAAAA", "AAAAAAAAAAAAAAAAAAAAAAAAAAAAAAAAA", "AAAAAAAAAAAAAAAAAAAAAAAAAAAAAAAAA", "AAAAAAAAAAAAAAAAAAAAAAAAAAAAAAAAA", "BAAAAAAAAEEAAAAAAAAAAAEEAAAAAAAAB", "BAAAAAAAEEAAAAAAAAAAAAAEEAAAAAAAB", "BAAAAAAAAAAAAAAAAAAAAAAAAAAAAAAAB", "CAAAAAAAAAAAAAAAAAAAAAAAAAAAAAAAC", "FAAAAAAAAAAAAAAAAAAAAAAAAAAAAAAAF", "IAAAAAAAAAAAAAAAAAAAAAAAAAAAAAAAI", "IAAAAAAAAAAAAAAAAAAAAAAAAAAAAAAAI", "EAAAAAAAAAAAAAAAAAAAAAAAAAAAAAAAE", "HAAAJJAAAJJJJAAAAAAAJJJJAAAJJAAAH", "EAAAAAAAAJJJJJAAKAAJJJJJAAAAAAAAE", "IAAAAAAAAJJJJAAAAAAAJJJJAAAAAAAAI", "IAAAAAAAAAAAAAAAAAAAAAAAAAAAAAAAI", "FAAAAAAAAAAAAAAAAAAAAAAAAAAAAAAAF", "CAAAAAAAAAAAAAAAAAAAAAAAAAAAAAAAC", "BAAAAAAAAAAAAAAAAAAAAAAAAAAAAAAAB", "BAAAAAAAEEAAAAAAAAAAAAAEEAAAAAAAB", "BAAAAAAAAEEAAAAAAAAAAAEEAAAAAAAAB", "AAAAAAAAAAAAAAAAAAAAAAAAAAAAAAAAA", "AAAAAAAAAAAAAAAAAAAAAAAAAAAAAAAAA", "AAAAAAAAAAAAAAAAAAAAAAAAAAAAAAAAA", "AAAAAAAAAAAAAAAAAAAAAAAAAAAAAAAAA", "AAAAAAAAAAAAAAAAAAAAAAAAAAAAAAAAA", "AAAAAAAAAAAAAAAAAAAAAAAAAAAAAAAAA", "AAAAAAAAAAAAAAAAAAAAAAAAAAAAAAAAA", "AAAAAAAABBBAACCEGECCAABBBAAAAAAAA")
        .aisle("AAAAAAABBBAAAACCDCCAAAABBBAAAAAAA", "AAAAAAAAAAAAAAAAAAAAAAAAAAAAAAAAA", "AAAAAAAAAAAAAAAAAAAAAAAAAAAAAAAAA", "AAAAAAAAAAAAAAAAAAAAAAAAAAAAAAAAA", "AAAAAAAAAAAAAAAAAAAAAAAAAAAAAAAAA", "AAAAAAAAAAAAAAAAAAAAAAAAAAAAAAAAA", "AAAAAAAAAAAAAAAAAAAAAAAAAAAAAAAAA", "BAAAAAAAAAAAAAAAAAAAAAAAAAAAAAAAB", "BAAAAAAAAAAAAAAAAAAAAAAAAAAAAAAAB", "BAAAAAAAEEAAAAAAAAAAAAAEEAAAAAAAB", "AAAAAAAEEAAAAAAAAAAAAAAAEEAAAAAAA", "CAAAAAAEEAAAAAAAAAAAAAAAEEAAAAAAC", "CAAAAAAEEAAAAAAAAAAAAAAAEEAAAAAAC", "FAAAAAAEEAAAAAAAAAAAAAAAEEAAAAAAF", "GAAAAAAEEAAAAAAAAAAAAAAAEEAAAAAAG", "EAAAAAAEEAAAAAAAAAAAAAAAEEAAAAAAE", "HAAAAJJEEAJJJJJJJJJJJJJAEJJJAAAAH", "EAAAAAAEEAJJJJJJJJJJJJJAEEAAAAAAE", "GAAAAAAEEAJJJJJJJJJJJJJAEEAAAAAAG", "FAAAAAAEEAAAAAAAAAAAAAAAEEAAAAAAF", "CAAAAAAEEAAAAAAAAAAAAAAAEEAAAAAAC", "CAAAAAAEEAAAAAAAAAAAAAAAEEAAAAAAC", "AAAAAAAEEAAAAAAAAAAAAAAAEEAAAAAAA", "BAAAAAAAEEAAAAAAAAAAAAAEEAAAAAAAB", "BAAAAAAAAAAAAAAAAAAAAAAAAAAAAAAAB", "BAAAAAAAAAAAAAAAAAAAAAAAAAAAAAAAB", "AAAAAAAAAAAAAAAAAAAAAAAAAAAAAAAAA", "AAAAAAAAAAAAAAAAAAAAAAAAAAAAAAAAA", "AAAAAAAAAAAAAAAAAAAAAAAAAAAAAAAAA", "AAAAAAAAAAAAAAAAAAAAAAAAAAAAAAAAA", "AAAAAAAAAAAAAAAAAAAAAAAAAAAAAAAAA", "AAAAAAAAAAAAAAAAAAAAAAAAAAAAAAAAA", "AAAAAAABBBAAAACCGCCAAAABBBAAAAAAA")
        .aisle("AAAAAABBBAAAAAACCCAAAAAABBBAAAAAA", "AAAAAAAAAAAAAAAAAAAAAAAAAAAAAAAAA", "AAAAAAAAAAAAAAAAAAAAAAAAAAAAAAAAA", "AAAAAAAAAAAAAAAAAAAAAAAAAAAAAAAAA", "AAAAAAAAAAAAAAAAAAAAAAAAAAAAAAAAA", "AAAAAAAAAAAAAAAAAAAAAAAAAAAAAAAAA", "BAAAAAAAAAAAAAAAAAAAAAAAAAAAAAAAB", "BAAAAAAAAAAAAAAAAAAAAAAAAAAAAAAAB", "BAAAAAAAAAAAAAAAAAAAAAAAAAAAAAAAB", "AAAAAAAAAAAAAAAAAAAAAAAAAAAAAAAAA", "AAAAAAAEEAAAAAAAAAAAAAAAEEAAAAAAA", "AAAAAAAEEAAAAAAAAAAAAAAAEEAAAAAAA", "CAAAAAAEEAAAAAAAAAAAAAAAEEAAAAAAC", "CAAAAAAEEAAAAAAAAAAAAAAAEEAAAAAAC", "FAAAAAAEEAAAAAAAAAAAAAAAEEAAAAAAF", "EAAAAAAEEAAAAAAAAAAAAAAAEEAAAAAAE", "DAAAAAJJEAAAJJJJJJJJJAAAJJJAAAAAD", "EAAAAAAEEAAJJJJJJJJJJJAAEEAAAAAAE", "FAAAAAAEEAAAJJJJJJJJJAAAEEAAAAAAF", "CAAAAAAEEAAAAAAAAAAAAAAAEEAAAAAAC", "CAAAAAAEEAAAAAAAAAAAAAAAEEAAAAAAC", "AAAAAAAEEAAAAAAAAAAAAAAAEEAAAAAAA", "AAAAAAAEEAAAAAAAAAAAAAAAEEAAAAAAA", "AAAAAAAAAAAAAAAAAAAAAAAAAAAAAAAAA", "BAAAAAAAAAAAAAAAAAAAAAAAAAAAAAAAB", "BAAAAAAAAAAAAAAAAAAAAAAAAAAAAAAAB", "BAAAAAAAAAAAAAAAAAAAAAAAAAAAAAAAB", "AAAAAAAAAAAAAAAAAAAAAAAAAAAAAAAAA", "AAAAAAAAAAAAAAAAAAAAAAAAAAAAAAAAA", "AAAAAAAAAAAAAAAAAAAAAAAAAAAAAAAAA", "AAAAAAAAAAAAAAAAAAAAAAAAAAAAAAAAA", "AAAAAAAAAAAAAAAAAAAAAAAAAAAAAAAAA", "AAAAAABBBAAAAAACCCAAAAAABBBAAAAAA")
        .aisle("AAAAABBBAAAAAAAACAAAAAAAABBBAAAAA", "AAAAAAAAAAAAAAAAAAAAAAAAAAAAAAAAA", "AAAAAAAAAAAAAAAAAAAAAAAAAAAAAAAAA", "AAAAAAAAAAAAAAAAAAAAAAAAAAAAAAAAA", "AAAAAAAAAAAAAAAAAAAAAAAAAAAAAAAAA", "BAAAAAAAAAAAAAAAAAAAAAAAAAAAAAAAB", "BAAAAAAAAAAAAAAAAAAAAAAAAAAAAAAAB", "BAAAAAAAAAAAAAAAAAAAAAAAAAAAAAAAB", "AAAAAAAAAAAAAAAAAAAAAAAAAAAAAAAAA", "AAAAAAAAAAAAAAAAAAAAAAAAAAAAAAAAA", "AAAAAAAAAAAAAAAAAAAAAAAAAAAAAAAAA", "AAAAAAAAAAAAAAAAAAAAAAAAAAAAAAAAA", "AAAAAAAAAAAAAAAAAAAAAAAAAAAAAAAAA", "CAAAAAAAAAAAAAAAAAAAAAAAAAAAAAAAC", "CAAAAAAAAAAAAAAAAAAAAAAAAAAAAAAAC", "EAAAAAAAAAAAAAAAAAAAAAAAAAAAAAAAE", "DAAAAAAJJAAAAAAJJJAAAAAAJJAAAAAAD", "EAAAAAAAAAAAAJJJJJJJAAAAAAAAAAAAE", "CAAAAAAAAAAAAAAJJJAAAAAAAAAAAAAAC", "CAAAAAAAAAAAAAAAAAAAAAAAAAAAAAAAC", "AAAAAAAAAAAAAAAAAAAAAAAAAAAAAAAAA", "AAAAAAAAAAAAAAAAAAAAAAAAAAAAAAAAA", "AAAAAAAAAAAAAAAAAAAAAAAAAAAAAAAAA", "AAAAAAAAAAAAAAAAAAAAAAAAAAAAAAAAA", "AAAAAAAAAAAAAAAAAAAAAAAAAAAAAAAAA", "BAAAAAAAAAAAAAAAAAAAAAAAAAAAAAAAB", "BAAAAAAAAAAAAAAAAAAAAAAAAAAAAAAAB", "BAAAAAAAAAAAAAAAAAAAAAAAAAAAAAAAB", "AAAAAAAAAAAAAAAAAAAAAAAAAAAAAAAAA", "AAAAAAAAAAAAAAAAAAAAAAAAAAAAAAAAA", "AAAAAAAAAAAAAAAAAAAAAAAAAAAAAAAAA", "AAAAAAAAAAAAAAAAAAAAAAAAAAAAAAAAA", "AAAAABBBAAAAAAAACAAAAAAAABBBAAAAA")
        .aisle("AAAABBBAAAAAAAAAAAAAAAAAAABBBAAAA", "AAAAAAAAAAAAAAAAAAAAAAAAAAAAAAAAA", "AAAAAAAAAAAAAAAAAAAAAAAAAAAAAAAAA", "AAAAAAAAAAAAAAAAAAAAAAAAAAAAAAAAA", "BAAAAAAAAAAAAAAAAAAAAAAAAAAAAAAAB", "BAAAAAAAAAAAAAAAAAAAAAAAAAAAAAAAB", "BAAAAAAAAAAAAAAAAAAAAAAAAAAAAAAAB", "AAAAAAAAAAAAAAAAAAAAAAAAAAAAAAAAA", "AAAAAAAAAAAAAAAAAAAAAAAAAAAAAAAAA", "AAAAAAAAAAAAAAAAAAAAAAAAAAAAAAAAA", "AAAAAAAAAAAAAAAAAAAAAAAAAAAAAAAAA", "AAAAAAAAAAAAAAAAAAAAAAAAAAAAAAAAA", "AAAAAAAAAAAAAAAAAAAAAAAAAAAAAAAAA", "AAAAAAAAAAAAAAAAAAAAAAAAAAAAAAAAA", "CAAAAAAAAAAAAAAAAAAAAAAAAAAAAAAAC", "CAAAAAAAAAAAAAAAAAAAAAAAAAAAAAAAC", "DAAAAAAAJJAAAAAAAAAAAAAJJAAAAAAAD", "CAAAAAAAAAAAAAAAAAAAAAAAAAAAAAAAC", "CAAAAAAAAAAAAAAAAAAAAAAAAAAAAAAAC", "AAAAAAAAAAAAAAAAAAAAAAAAAAAAAAAAA", "AAAAAAAAAAAAAAAAAAAAAAAAAAAAAAAAA", "AAAAAAAAAAAAAAAAAAAAAAAAAAAAAAAAA", "AAAAAAAAAAAAAAAAAAAAAAAAAAAAAAAAA", "AAAAAAAAAAAAAAAAAAAAAAAAAAAAAAAAA", "AAAAAAAAAAAAAAAAAAAAAAAAAAAAAAAAA", "AAAAAAAAAAAAAAAAAAAAAAAAAAAAAAAAA", "BAAAAAAAAAAAAAAAAAAAAAAAAAAAAAAAB", "BAAAAAAAAAAAAAAAAAAAAAAAAAAAAAAAB", "BAAAAAAAAAAAAAAAAAAAAAAAAAAAAAAAB", "AAAAAAAAAAAAAAAAAAAAAAAAAAAAAAAAA", "AAAAAAAAAAAAAAAAAAAAAAAAAAAAAAAAA", "AAAAAAAAAAAAAAAAAAAAAAAAAAAAAAAAA", "AAAABBBAAAAAAAAAAAAAAAAAAABBBAAAA")
        .aisle("AAABBBAAAAAAAAAAAAAAAAAAAAABBBAAA", "AAAAAAAAAAAAAAAAAAAAAAAAAAAAAAAAA", "AAAAAAAAAAAAAAAAAAAAAAAAAAAAAAAAA", "BAAAAAAAAAAAAAAAAAAAAAAAAAAAAAAAB", "BAAAAAAAAAAAAAAAAAAAAAAAAAAAAAAAB", "BAAAAAAAAAAAAAAAAAAAAAAAAAAAAAAAB", "AAAAAAAAAAAAAAAAAAAAAAAAAAAAAAAAA", "AAAAAAAAAAAAAAAAAAAAAAAAAAAAAAAAA", "AAAAAAAAAAAAAAAAAAAAAAAAAAAAAAAAA", "AAAAAAAAAAAAAAAAAAAAAAAAAAAAAAAAA", "AAAAAAAAAAAAAAAAAAAAAAAAAAAAAAAAA", "AAAAAAAAAAAAAAAAAAAAAAAAAAAAAAAAA", "AAAAAAAAAAAAAAAAAAAAAAAAAAAAAAAAA", "AAAAAAAAAAAAAAAAAAAAAAAAAAAAAAAAA", "AAAAAAAAAAAAAAAAAAAAAAAAAAAAAAAAA", "CAAAAAAAAAAAAAAAAAAAAAAAAAAAAAAAC", "CAAAAAAAAJJAAAAAAAAAAAJJAAAAAAAAC", "CAAAAAAAAAAAAAAAAAAAAAAAAAAAAAAAC", "AAAAAAAAAAAAAAAAAAAAAAAAAAAAAAAAA", "AAAAAAAAAAAAAAAAAAAAAAAAAAAAAAAAA", "AAAAAAAAAAAAAAAAAAAAAAAAAAAAAAAAA", "AAAAAAAAAAAAAAAAAAAAAAAAAAAAAAAAA", "AAAAAAAAAAAAAAAAAAAAAAAAAAAAAAAAA", "AAAAAAAAAAAAAAAAAAAAAAAAAAAAAAAAA", "AAAAAAAAAAAAAAAAAAAAAAAAAAAAAAAAA", "AAAAAAAAAAAAAAAAAAAAAAAAAAAAAAAAA", "AAAAAAAAAAAAAAAAAAAAAAAAAAAAAAAAA", "BAAAAAAAAAAAAAAAAAAAAAAAAAAAAAAAB", "BAAAAAAAAAAAAAAAAAAAAAAAAAAAAAAAB", "BAAAAAAAAAAAAAAAAAAAAAAAAAAAAAAAB", "AAAAAAAAAAAAAAAAAAAAAAAAAAAAAAAAA", "AAAAAAAAAAAAAAAAAAAAAAAAAAAAAAAAA", "AAABBBAAAAAAAAAAAAAAAAAAAAABBBAAA")
        .aisle("AABBBAAAAAAAAAAAAAAAAAAAAAAABBBAA", "AAAAAAAAAAAAAAAAAAAAAAAAAAAAAAAAA", "BAAAAAAAAAAAAAAAAAAAAAAAAAAAAAAAB", "BAAAAAAAAAAAAAAAAAAAAAAAAAAAAAAAB", "BAAAAAAAAAAAAAAAAAAAAAAAAAAAAAAAB", "AAAAAAAAAAAAAAAAAAAAAAAAAAAAAAAAA", "AAAAAAAAAAAAAAAAAAAAAAAAAAAAAAAAA", "AAAAAAAAAAAAAAAAAAAAAAAAAAAAAAAAA", "AAAAAAAAAAAAAAAAAAAAAAAAAAAAAAAAA", "AAAAAAAAAAAAAAAAAAAAAAAAAAAAAAAAA", "AAAAAAAAAAAAAAAAAAAAAAAAAAAAAAAAA", "AAAAAAAAAAAAAAAAAAAAAAAAAAAAAAAAA", "AAAAAAAAAAAAAAAAAAAAAAAAAAAAAAAAA", "AAAAAAAAAAAAAAAAAAAAAAAAAAAAAAAAA", "AAAAAAAAAAAAAAAAAAAAAAAAAAAAAAAAA", "AAAAAAAAAAAAAAAAAAAAAAAAAAAAAAAAA", "CAAAAAAAAAJJAAAAAAAAAJJAAAAAAAAAC", "AAAAAAAAAAAAAAAAAAAAAAAAAAAAAAAAA", "AAAAAAAAAAAAAAAAAAAAAAAAAAAAAAAAA", "AAAAAAAAAAAAAAAAAAAAAAAAAAAAAAAAA", "AAAAAAAAAAAAAAAAAAAAAAAAAAAAAAAAA", "AAAAAAAAAAAAAAAAAAAAAAAAAAAAAAAAA", "AAAAAAAAAAAAAAAAAAAAAAAAAAAAAAAAA", "AAAAAAAAAAAAAAAAAAAAAAAAAAAAAAAAA", "AAAAAAAAAAAAAAAAAAAAAAAAAAAAAAAAA", "AAAAAAAAAAAAAAAAAAAAAAAAAAAAAAAAA", "AAAAAAAAAAAAAAAAAAAAAAAAAAAAAAAAA", "AAAAAAAAAAAAAAAAAAAAAAAAAAAAAAAAA", "BAAAAAAAAAAAAAAAAAAAAAAAAAAAAAAAB", "BAAAAAAAAAAAAAAAAAAAAAAAAAAAAAAAB", "BAAAAAAAAAAAAAAAAAAAAAAAAAAAAAAAB", "AAAAAAAAAAAAAAAAAAAAAAAAAAAAAAAAA", "AABBBAAAAAAAAAAAAAAAAAAAAAAABBBAA")
        .aisle("ABBBAAAAAAAAAAAAAAAAAAAAAAAAABBBA", "BAAAAAAAAAAAAAAAAAAAAAAAAAAAAAAAB", "BAAAAAAAAAAAAAAAAAAAAAAAAAAAAAAAB", "BAAAAAAAAAAAAAAAAAAAAAAAAAAAAAAAB", "AAAAAAAAAAAAAAAAAAAAAAAAAAAAAAAAA", "AAAAAAAAAAAAAAAAAAAAAAAAAAAAAAAAA", "AAAAAAAAAAAAAAAAAAAAAAAAAAAAAAAAA", "AAAAAAAAAAAAAAAAAAAAAAAAAAAAAAAAA", "AAAAAAAAAAAAAAAAAAAAAAAAAAAAAAAAA", "AAAAAAAAAAAAAAAAAAAAAAAAAAAAAAAAA", "AAAAAAAAAAAAAAAAAAAAAAAAAAAAAAAAA", "AAAAAAAAAAAAAAAAAAAAAAAAAAAAAAAAA", "AAAAAAAAAAAAAAAAAAAAAAAAAAAAAAAAA", "AAAAAAAAAAAAAAAAAAAAAAAAAAAAAAAAA", "AAAAAAAAAAAAAAAAAAAAAAAAAAAAAAAAA", "AAAAAAAAAAAAAAAAAAAAAAAAAAAAAAAAA", "AAAAAAAAAAAJJAAAAAAAJJAAAAAAAAAAA", "AAAAAAAAAAAAAAAAAAAAAAAAAAAAAAAAA", "AAAAAAAAAAAAAAAAAAAAAAAAAAAAAAAAA", "AAAAAAAAAAAAAAAAAAAAAAAAAAAAAAAAA", "AAAAAAAAAAAAAAAAAAAAAAAAAAAAAAAAA", "AAAAAAAAAAAAAAAAAAAAAAAAAAAAAAAAA", "AAAAAAAAAAAAAAAAAAAAAAAAAAAAAAAAA", "AAAAAAAAAAAAAAAAAAAAAAAAAAAAAAAAA", "AAAAAAAAAAAAAAAAAAAAAAAAAAAAAAAAA", "AAAAAAAAAAAAAAAAAAAAAAAAAAAAAAAAA", "AAAAAAAAAAAAAAAAAAAAAAAAAAAAAAAAA", "AAAAAAAAAAAAAAAAAAAAAAAAAAAAAAAAA", "AAAAAAAAAAAAAAAAAAAAAAAAAAAAAAAAA", "BAAAAAAAAAAAAAAAAAAAAAAAAAAAAAAAB", "BAAAAAAAAAAAAAAAAAAAAAAAAAAAAAAAB", "BAAAAAAAAAAAAAAAAAAAAAAAAAAAAAAAB", "ABBBAAAAAAAAAAAAAAAAAAAAAAAAABBBA")
        .aisle("BBBAAAAAAAAAAAAAAAAAAAAAAAAAAABBB", "BAAAAAAAAAAAAAAAAAAAAAAAAAAAAAAAB", "BAAAAAAAAAAAAAAAAAAAAAAAAAAAAAAAB", "AAAAAAAAAAAAAAAAAAAAAAAAAAAAAAAAA", "AAAAAAAAAAAAAAAAAAAAAAAAAAAAAAAAA", "AAAAAAAAAAAAAAAAAAAAAAAAAAAAAAAAA", "AAAAAAAAAAAAAAAAAAAAAAAAAAAAAAAAA", "AAAAAAAAAAAAAAAAAAAAAAAAAAAAAAAAA", "AAAAAAAAAAAAAAAAAAAAAAAAAAAAAAAAA", "AAAAAAAAAAAAAAAAAAAAAAAAAAAAAAAAA", "AAAAAAAAAAAAAAAAAAAAAAAAAAAAAAAAA", "AAAAAAAAAAAAAAAAAAAAAAAAAAAAAAAAA", "AAAAAAAAAAAAAAAAAAAAAAAAAAAAAAAAA", "AAAAAAAAAAAAAAAAAAAAAAAAAAAAAAAAA", "AAAAAAAAAAAAAAAAAAAAAAAAAAAAAAAAA", "AAAAAAAAAAAAAGGGGGGGAAAAAAAAAAAAA", "AAAAAAAAAAAAJJGGGGGJJAAAAAAAAAAAA", "AAAAAAAAAAAAAGGGGGGGAAAAAAAAAAAAA", "AAAAAAAAAAAAAAAAAAAAAAAAAAAAAAAAA", "AAAAAAAAAAAAAAAAAAAAAAAAAAAAAAAAA", "AAAAAAAAAAAAAAAAAAAAAAAAAAAAAAAAA", "AAAAAAAAAAAAAAAAAAAAAAAAAAAAAAAAA", "AAAAAAAAAAAAAAAAAAAAAAAAAAAAAAAAA", "AAAAAAAAAAAAAAAAAAAAAAAAAAAAAAAAA", "AAAAAAAAAAAAAAAAAAAAAAAAAAAAAAAAA", "AAAAAAAAAAAAAAAAAAAAAAAAAAAAAAAAA", "AAAAAAAAAAAAAAAAAAAAAAAAAAAAAAAAA", "AAAAAAAAAAAAAAAAAAAAAAAAAAAAAAAAA", "AAAAAAAAAAAAAAAAAAAAAAAAAAAAAAAAA", "AAAAAAAAAAAAAAAAAAAAAAAAAAAAAAAAA", "BAAAAAAAAAAAAAAAAAAAAAAAAAAAAAAAB", "BAAAAAAAAAAAAAAAAAAAAAAAAAAAAAAAB", "BBBAAAAAAAAAAAAAAAAAAAAAAAAAAABBB")
        .aisle("BBAAAAAAAAAAAAAAAAAAAAAAAAAAAAABB", "BBBAAAAAAAAAAAAAAAAAAAAAAAAAAABBB", "ABBBAAAAAAAAAAAAAAAAAAAAAAAAABBBA", "AABBBAAAAAAAAAAACAAAAAAAAAAABBBAA", "AAABBBAAAAAAAAACCCAAAAAAAAABBBAAA", "AAAABBBAAAAAAACCDCCAAAAAAABBBAAAA", "AAAAABBBAAAAACCEDECCAAAAABBBAAAAA", "AAAAAABBBAAACCFEDEFCCAAABBBAAAAAA", "AAAAAAABBBACCFGEHEGFCCABBBAAAAAAA", "AAAAAAAABBBCFIIEHEIIFCBBBAAAAAAAA", "AAAAAAAAABBBFIIEHEIIFBBBAAAAAAAAA", "AAAAAAAACCBBBFGEHEGFBBBCCAAAAAAAA", "AAAAAAACCFFBBBFEGEFBBBFFCCAAAAAAA", "AAAAAACCFIIFBBBEGEBBBFIIFCCAAAAAA", "AAAAACCFGIIGFBBBGBBBFGIIGFCCAAAAA", "AAAACCEEEEEEEEBBBBBEEEEEEEECCAAAA", "AAACCDDDHHHHGGGBSBGGGHHHHDDDCCAAA", "AAAACCEEEEEEEEBBBBBEEEEEEEECCAAAA", "AAAAACCFGIIGFBBBGBBBFGIIGFCCAAAAA", "AAAAAACCFIIFBBBEGEBBBFIIFCCAAAAAA", "AAAAAAACCFFBBBFEGEFBBBFFCCAAAAAAA", "AAAAAAAACCBBBFGEHEGFBBBCCAAAAAAAA", "AAAAAAAAABBBFIIEHEIIFBBBAAAAAAAAA", "AAAAAAAABBBCFIIEHEIIFCBBBAAAAAAAA", "AAAAAAABBBACCFGEHEGFCCABBBAAAAAAA", "AAAAAABBBAAACCFEDEFCCAAABBBAAAAAA", "AAAAABBBAAAAACCEDECCAAAAABBBAAAAA", "AAAABBBAAAAAAACCDCCAAAAAAABBBAAAA", "AAABBBAAAAAAAAACCCAAAAAAAAABBBAAA", "AABBBAAAAAAAAAAACAAAAAAAAAAABBBAA", "ABBBAAAAAAAAAAAAAAAAAAAAAAAAABBBA", "BBBAAAAAAAAAAAAAAAAAAAAAAAAAAABBB", "BBAAAAAAAAAAAAAAAAAAAAAAAAAAAAABB")
           .where("A", Predicates.blocks("minecraft:air"))
           .where("B", Predicates.blocks("kubejs:phoenix_enriched_tritanium_casing").setMinGlobalLimited(10)
           .or(Predicates.abilities(PartAbility.MAINTENANCE).setMaxGlobalLimited(1))
           .or(Predicates.abilities(PartAbility.PARALLEL_HATCH).setMaxGlobalLimited(1))
           .or(Predicates.abilities(PartAbility.INPUT_LASER).setMaxGlobalLimited(1))
           .or(Predicates.autoAbilities(definition.getRecipeTypes())))
           .where("C", Predicates.blocks("gtceu:phoenix_enriched_tritanium_frame"))
           .where("D", Predicates.blocks("gtceu:advanced_computer_casing"))
           .where("E", Predicates.blocks("gtceu:neutronium_frame"))
           .where("F", Predicates.blocks("gtceu:computer_casing"))
           .where("G", Predicates.blocks("kubejs:true_heat_stable_coil_block"))
           .where("H", Predicates.blocks("kubejs:stable_logic"))
           .where("I", Predicates.blocks("gtceu:hpca_bridge_component"))
           .where("J", Predicates.blocks("kubejs:reliable_naquadah_alloy_machine_casing"))
           .where("K", Predicates.blocks("gtceu:phoenix_enriched_naquad_frame"))
           .where("L", Predicates.blocks("kubejs:super_stable_fusion_casing")
                   .or(Predicates.blocks("kubejs:phoenix_gaze_panel").setMaxGlobalLimited(60)))                                                    
           .where("M", Predicates.blocks("kubejs:blazing_core_stabilizer"))
           .where("N", Predicates.blocks("draconicevolution:awakened_draconium_block"))
           .where("O", Predicates.blocks("expatternprovider:fishbig"))
           .where("P", Predicates.blocks("kubejs:glitched_entropy_casing"))
           .where("Q", Predicates.blocks("ae2:creative_energy_cell"))
           .where("R", Predicates.blocks("kubejs:phoenix_heart_casing"))
           .where('S', Predicates.controller(Predicates.blocks(definition.get())))
                    .build())
                    .workableCasingRenderer('kubejs:block/phoenix_enriched_tritanium_casing', 'gtceu:block/multiblock/fusion_reactor', false)
        });           */                                                                                                                                 